[2025-02-08 12:06:50,668] {taskinstance.py:1032} INFO - Dependencies all met for <TaskInstance: LocalIngestionDag.wget scheduled__2023-02-02T06:00:00+00:00 [queued]>
[2025-02-08 12:06:50,679] {taskinstance.py:1032} INFO - Dependencies all met for <TaskInstance: LocalIngestionDag.wget scheduled__2023-02-02T06:00:00+00:00 [queued]>
[2025-02-08 12:06:50,679] {taskinstance.py:1238} INFO - 
--------------------------------------------------------------------------------
[2025-02-08 12:06:50,679] {taskinstance.py:1239} INFO - Starting attempt 2 of 2
[2025-02-08 12:06:50,679] {taskinstance.py:1240} INFO - 
--------------------------------------------------------------------------------
[2025-02-08 12:06:50,691] {taskinstance.py:1259} INFO - Executing <Task(BashOperator): wget> on 2023-02-02 06:00:00+00:00
[2025-02-08 12:06:50,697] {standard_task_runner.py:52} INFO - Started process 1950 to run task
[2025-02-08 12:06:50,701] {standard_task_runner.py:76} INFO - Running: ['***', 'tasks', 'run', 'LocalIngestionDag', 'wget', 'scheduled__2023-02-02T06:00:00+00:00', '--job-id', '107', '--raw', '--subdir', 'DAGS_FOLDER/data_ingestion_local.py', '--cfg-path', '/tmp/tmpb4tn_kfk', '--error-file', '/tmp/tmpjurvawda']
[2025-02-08 12:06:50,705] {standard_task_runner.py:77} INFO - Job 107: Subtask wget
[2025-02-08 12:06:50,781] {logging_mixin.py:109} INFO - Running <TaskInstance: LocalIngestionDag.wget scheduled__2023-02-02T06:00:00+00:00 [running]> on host dfc301afada6
[2025-02-08 12:06:50,861] {taskinstance.py:1426} INFO - Exporting the following env vars:
AIRFLOW_CTX_DAG_OWNER=***
AIRFLOW_CTX_DAG_ID=LocalIngestionDag
AIRFLOW_CTX_TASK_ID=wget
AIRFLOW_CTX_EXECUTION_DATE=2023-02-02T06:00:00+00:00
AIRFLOW_CTX_DAG_RUN_ID=scheduled__2023-02-02T06:00:00+00:00
[2025-02-08 12:06:50,862] {subprocess.py:62} INFO - Tmp dir root location: 
 /tmp
[2025-02-08 12:06:50,863] {subprocess.py:74} INFO - Running command: ['bash', '-c', 'curl https://d37ci6vzurychx.cloudfront.net/trip-data/yellow_tripdata_2021-01.parquet -O /opt/***/output.parquet']
[2025-02-08 12:06:50,879] {subprocess.py:85} INFO - Output:
[2025-02-08 12:06:50,891] {subprocess.py:89} INFO -   % Total    % Received % Xferd  Average Speed   Time    Time     Time  Current
[2025-02-08 12:06:50,891] {subprocess.py:89} INFO -                                  Dload  Upload   Total   Spent    Left  Speed
[2025-02-08 12:06:51,072] {subprocess.py:89} INFO -   0     0    0     0    0     0      0      0 --:--:-- --:--:-- --:--:--     0100 20.6M  100 20.6M    0     0   114M      0 --:--:-- --:--:-- --:--:--  114M
[2025-02-08 12:06:51,072] {subprocess.py:89} INFO - curl: (3) URL using bad/illegal format or missing URL
[2025-02-08 12:06:51,074] {subprocess.py:93} INFO - Command exited with return code 3
[2025-02-08 12:06:51,099] {taskinstance.py:1700} ERROR - Task failed with exception
Traceback (most recent call last):
  File "/home/airflow/.local/lib/python3.6/site-packages/airflow/models/taskinstance.py", line 1329, in _run_raw_task
    self._execute_task_with_callbacks(context)
  File "/home/airflow/.local/lib/python3.6/site-packages/airflow/models/taskinstance.py", line 1455, in _execute_task_with_callbacks
    result = self._execute_task(context, self.task)
  File "/home/airflow/.local/lib/python3.6/site-packages/airflow/models/taskinstance.py", line 1511, in _execute_task
    result = execute_callable(context=context)
  File "/home/airflow/.local/lib/python3.6/site-packages/airflow/operators/bash.py", line 188, in execute
    f'Bash command failed. The command returned a non-zero exit code {result.exit_code}.'
airflow.exceptions.AirflowException: Bash command failed. The command returned a non-zero exit code 3.
[2025-02-08 12:06:51,107] {taskinstance.py:1277} INFO - Marking task as FAILED. dag_id=LocalIngestionDag, task_id=wget, execution_date=20230202T060000, start_date=20250208T120650, end_date=20250208T120651
[2025-02-08 12:06:51,127] {standard_task_runner.py:92} ERROR - Failed to execute job 107 for task wget
Traceback (most recent call last):
  File "/home/airflow/.local/lib/python3.6/site-packages/airflow/task/task_runner/standard_task_runner.py", line 85, in _start_by_fork
    args.func(args, dag=self.dag)
  File "/home/airflow/.local/lib/python3.6/site-packages/airflow/cli/cli_parser.py", line 48, in command
    return func(*args, **kwargs)
  File "/home/airflow/.local/lib/python3.6/site-packages/airflow/utils/cli.py", line 92, in wrapper
    return f(*args, **kwargs)
  File "/home/airflow/.local/lib/python3.6/site-packages/airflow/cli/commands/task_command.py", line 298, in task_run
    _run_task_by_selected_method(args, dag, ti)
  File "/home/airflow/.local/lib/python3.6/site-packages/airflow/cli/commands/task_command.py", line 107, in _run_task_by_selected_method
    _run_raw_task(args, ti)
  File "/home/airflow/.local/lib/python3.6/site-packages/airflow/cli/commands/task_command.py", line 184, in _run_raw_task
    error_file=args.error_file,
  File "/home/airflow/.local/lib/python3.6/site-packages/airflow/utils/session.py", line 70, in wrapper
    return func(*args, session=session, **kwargs)
  File "/home/airflow/.local/lib/python3.6/site-packages/airflow/models/taskinstance.py", line 1329, in _run_raw_task
    self._execute_task_with_callbacks(context)
  File "/home/airflow/.local/lib/python3.6/site-packages/airflow/models/taskinstance.py", line 1455, in _execute_task_with_callbacks
    result = self._execute_task(context, self.task)
  File "/home/airflow/.local/lib/python3.6/site-packages/airflow/models/taskinstance.py", line 1511, in _execute_task
    result = execute_callable(context=context)
  File "/home/airflow/.local/lib/python3.6/site-packages/airflow/operators/bash.py", line 188, in execute
    f'Bash command failed. The command returned a non-zero exit code {result.exit_code}.'
airflow.exceptions.AirflowException: Bash command failed. The command returned a non-zero exit code 3.
[2025-02-08 12:06:51,154] {local_task_job.py:154} INFO - Task exited with return code 1
[2025-02-08 12:06:51,213] {local_task_job.py:264} INFO - 0 downstream tasks scheduled from follow-on schedule check
