[2025-02-08 14:27:28,968] {taskinstance.py:1032} INFO - Dependencies all met for <TaskInstance: LocalIngestionDag.wget scheduled__2023-02-02T06:00:00+00:00 [queued]>
[2025-02-08 14:27:28,985] {taskinstance.py:1032} INFO - Dependencies all met for <TaskInstance: LocalIngestionDag.wget scheduled__2023-02-02T06:00:00+00:00 [queued]>
[2025-02-08 14:27:28,985] {taskinstance.py:1238} INFO - 
--------------------------------------------------------------------------------
[2025-02-08 14:27:28,985] {taskinstance.py:1239} INFO - Starting attempt 7 of 7
[2025-02-08 14:27:28,985] {taskinstance.py:1240} INFO - 
--------------------------------------------------------------------------------
[2025-02-08 14:27:29,000] {taskinstance.py:1259} INFO - Executing <Task(BashOperator): wget> on 2023-02-02 06:00:00+00:00
[2025-02-08 14:27:29,006] {standard_task_runner.py:52} INFO - Started process 1448 to run task
[2025-02-08 14:27:29,009] {standard_task_runner.py:76} INFO - Running: ['***', 'tasks', 'run', 'LocalIngestionDag', 'wget', 'scheduled__2023-02-02T06:00:00+00:00', '--job-id', '118', '--raw', '--subdir', 'DAGS_FOLDER/data_ingestion_local.py', '--cfg-path', '/tmp/tmp0wgvjpgw', '--error-file', '/tmp/tmpwq035yss']
[2025-02-08 14:27:29,012] {standard_task_runner.py:77} INFO - Job 118: Subtask wget
[2025-02-08 14:27:29,246] {logging_mixin.py:109} INFO - Running <TaskInstance: LocalIngestionDag.wget scheduled__2023-02-02T06:00:00+00:00 [running]> on host 56ce40b7c807
[2025-02-08 14:27:29,299] {logging_mixin.py:109} WARNING - /home/***/.local/lib/python3.6/site-packages/***/utils/context.py:152 AirflowContextDeprecationWarning: Accessing 'execution_date' from the template is deprecated and will be removed in a future version. Please use 'data_interval_start' or 'logical_date' instead.
[2025-02-08 14:27:29,322] {taskinstance.py:1426} INFO - Exporting the following env vars:
AIRFLOW_CTX_DAG_OWNER=***
AIRFLOW_CTX_DAG_ID=LocalIngestionDag
AIRFLOW_CTX_TASK_ID=wget
AIRFLOW_CTX_EXECUTION_DATE=2023-02-02T06:00:00+00:00
AIRFLOW_CTX_DAG_RUN_ID=scheduled__2023-02-02T06:00:00+00:00
[2025-02-08 14:27:29,323] {subprocess.py:62} INFO - Tmp dir root location: 
 /tmp
[2025-02-08 14:27:29,323] {subprocess.py:74} INFO - Running command: ['bash', '-c', ' "2023-02"']
[2025-02-08 14:27:29,336] {subprocess.py:85} INFO - Output:
[2025-02-08 14:27:29,339] {subprocess.py:89} INFO - bash: 2023-02: command not found
[2025-02-08 14:27:29,340] {subprocess.py:93} INFO - Command exited with return code 127
[2025-02-08 14:27:29,356] {taskinstance.py:1700} ERROR - Task failed with exception
Traceback (most recent call last):
  File "/home/airflow/.local/lib/python3.6/site-packages/airflow/models/taskinstance.py", line 1329, in _run_raw_task
    self._execute_task_with_callbacks(context)
  File "/home/airflow/.local/lib/python3.6/site-packages/airflow/models/taskinstance.py", line 1455, in _execute_task_with_callbacks
    result = self._execute_task(context, self.task)
  File "/home/airflow/.local/lib/python3.6/site-packages/airflow/models/taskinstance.py", line 1511, in _execute_task
    result = execute_callable(context=context)
  File "/home/airflow/.local/lib/python3.6/site-packages/airflow/operators/bash.py", line 188, in execute
    f'Bash command failed. The command returned a non-zero exit code {result.exit_code}.'
airflow.exceptions.AirflowException: Bash command failed. The command returned a non-zero exit code 127.
[2025-02-08 14:27:29,364] {taskinstance.py:1277} INFO - Marking task as FAILED. dag_id=LocalIngestionDag, task_id=wget, execution_date=20230202T060000, start_date=20250208T142728, end_date=20250208T142729
[2025-02-08 14:27:29,380] {standard_task_runner.py:92} ERROR - Failed to execute job 118 for task wget
Traceback (most recent call last):
  File "/home/airflow/.local/lib/python3.6/site-packages/airflow/task/task_runner/standard_task_runner.py", line 85, in _start_by_fork
    args.func(args, dag=self.dag)
  File "/home/airflow/.local/lib/python3.6/site-packages/airflow/cli/cli_parser.py", line 48, in command
    return func(*args, **kwargs)
  File "/home/airflow/.local/lib/python3.6/site-packages/airflow/utils/cli.py", line 92, in wrapper
    return f(*args, **kwargs)
  File "/home/airflow/.local/lib/python3.6/site-packages/airflow/cli/commands/task_command.py", line 298, in task_run
    _run_task_by_selected_method(args, dag, ti)
  File "/home/airflow/.local/lib/python3.6/site-packages/airflow/cli/commands/task_command.py", line 107, in _run_task_by_selected_method
    _run_raw_task(args, ti)
  File "/home/airflow/.local/lib/python3.6/site-packages/airflow/cli/commands/task_command.py", line 184, in _run_raw_task
    error_file=args.error_file,
  File "/home/airflow/.local/lib/python3.6/site-packages/airflow/utils/session.py", line 70, in wrapper
    return func(*args, session=session, **kwargs)
  File "/home/airflow/.local/lib/python3.6/site-packages/airflow/models/taskinstance.py", line 1329, in _run_raw_task
    self._execute_task_with_callbacks(context)
  File "/home/airflow/.local/lib/python3.6/site-packages/airflow/models/taskinstance.py", line 1455, in _execute_task_with_callbacks
    result = self._execute_task(context, self.task)
  File "/home/airflow/.local/lib/python3.6/site-packages/airflow/models/taskinstance.py", line 1511, in _execute_task
    result = execute_callable(context=context)
  File "/home/airflow/.local/lib/python3.6/site-packages/airflow/operators/bash.py", line 188, in execute
    f'Bash command failed. The command returned a non-zero exit code {result.exit_code}.'
airflow.exceptions.AirflowException: Bash command failed. The command returned a non-zero exit code 127.
[2025-02-08 14:27:29,422] {local_task_job.py:154} INFO - Task exited with return code 1
[2025-02-08 14:27:29,611] {local_task_job.py:264} INFO - 0 downstream tasks scheduled from follow-on schedule check
